Workbook

Sheet Atividades
B1: Nome do Projeto | C1: COD Projeto | D1: coluna teste | E1: Atividades Macro | F1: Tarefa | G1: Responsável pela Atividade | H1: Data da Atividade | I1: Horas Utilizadas | J1: Status | K1: Observação
B2: Perfil dos Municípios | C2: =IF(B2<>"",VLOOKUP(B2,Projetos!E:F,2,0),"") -> 2 | E2: Planejamento do Projeto | F2: Análise e Levantamento das Informações | G2: Luis Eduardo | H2: 45301 | I2: 0.25 | J2: Finalizado
B3: Relatório de Sustentabilidade - IEL | C3: =IF(B3<>"",VLOOKUP(B3,Projetos!E:F,2,0),"") -> 10 | E3: Reunião | F3: Alinhamento de Informações | G3: Sandra Marcia | H3: 45301 | I3: 0.041666667 | J3: Finalizado
B4: Relatório de Sustentabilidade - IEL | C4: =IF(B4<>"",VLOOKUP(B4,Projetos!E:F,2,0),"") -> 10 | E4: Reunião | F4: Alinhamento de Informações | G4: Ely Bastos | H4: 45301 | I4: 0.041666667 | J4: Finalizado
B5: Perfil dos Municípios | C5: =IF(B5<>"",VLOOKUP(B5,Projetos!E:F,2,0),"") -> 2 | E5: Planejamento do Projeto | F5: Análise e Levantamento das Informações | G5: Luis Eduardo | H5: 45302 | I5: 0.083333333 | J5: Finalizado
B6: Perfil dos Municípios | C6: =IF(B6<>"",VLOOKUP(B6,Projetos!E:F,2,0),"") -> 2 | E6: Planejamento do Projeto | F6: Análise e Levantamento das Informações | G6: Diego Gomes | H6: 45302 | I6: 0.083333333 | J6: Finalizado
B7: Perfil dos Municípios | C7: =IF(B7<>"",VLOOKUP(B7,Projetos!E:F,2,0),"") -> 2 | E7: Estruturação do Projeto | F7: Documentação dos indicadores | G7: Luis Eduardo | H7: 45302 | I7: 0.16666667 | J7: Finalizado
B8: Perfil dos Municípios | C8: =IF(B8<>"",VLOOKUP(B8,Projetos!E:F,2,0),"") -> 2 | E8: Estruturação do Projeto | F8: Documentação dos indicadores | G8: Diego Gomes | H8: 45302 | I8: 0.083333333 | J8: Finalizado
B9: Relatório de Sustentabilidade - IEL | C9: =IF(B9<>"",VLOOKUP(B9,Projetos!E:F,2,0),"") -> 10 | E9: Relatório | F9: Elaboração do relatório | G9: Ely Bastos | H9: 45302 | I9: 0.33333333 | J9: Finalizado
B10: Relatório de Sustentabilidade - IEL | C10: =IF(B10<>"",VLOOKUP(B10,Projetos!E:F,2,0),"") -> 10 | E10: Validação | F10: Validação | G10: Sandra Marcia | H10: 45302 | I10: 0.083333333 | J10: Finalizado
B11: Perfil dos Municípios | C11: =IF(B11<>"",VLOOKUP(B11,Projetos!E:F,2,0),"") -> 2 | E11: Extração de Dados | F11: Extração do Banco conforme Documentação | G11: Marcus Vinícius | H11: 45303 | I11: 0.25 | J11: Finalizado
B12: Relatório de Sustentabilidade - IEL | C12: =IF(B12<>"",VLOOKUP(B12,Projetos!E:F,2,0),"") -> 10 | E12: Extração de Dados | F12: Extração de informações para relatório | G12: Luis Eduardo | H12: 45303 | I12: 0.16666667 | J12: Finalizado
B13: Relatório de Sustentabilidade - IEL | C13: =IF(B13<>"",VLOOKUP(B13,Projetos!E:F,2,0),"") -> 10 | E13: Relatório | F13: Elaboração do relatório | G13: Ely Bastos | H13: 45303 | I13: 0.33333333 | J13: Finalizado
... B537: Banco de Dados Mineração | C537: =IF(B537<>"",VLOOKUP(B537,Projetos!E:F,2,0),"") -> 24 | E537: Extração de Dados | F537: Testes de extração | G537: Marcus Vinícius | H537: 45455 | I537: 0.29166667 | J537: Finalizado
B538: Livro IFC | C538: =IF(B538<>"",VLOOKUP(B538,Projetos!E:F,2,0),"") -> 13 | E538: Reunião | F538: Reunião de Alinhamentos e ajustes do projeto IFC | G538: Luis Eduardo | H538: 45456 | I538: 0.083333333 | J538: Finalizado | K538: Realizamos uma reunião para entendermos onde estavamos no projeto, devido a multiplas paradas na execução para realização de outros, nos situamos quanto ao que já tinha sido realizado, o que deveria ser alterado, além de ações futuras no projeto, discutimos prolixidades e redundancias dos textos além de formas de vizualização e disposição do conteúdo que estamos elaborando. As ações de reunião neste projeto serão constantes, visto a necessidade de alinhamento
B539: Livro IFC | C539: =IF(B539<>"",VLOOKUP(B539,Projetos!E:F,2,0),"") -> 13 | E539: Reunião | F539: Reunião de Alinhamentos e ajustes do projeto IFC | G539: Ely Bastos | H539: 45456 | I539: 0.083333333 | J539: Finalizado
B540: Livro IFC | C540: =IF(B540<>"",VLOOKUP(B540,Projetos!E:F,2,0),"") -> 13 | E540: Relatório | F540: Escrita de textos do livro IFC | G540: Luis Eduardo | H540: 45456 | I540: 0.16666667 | J540: Finalizado
B541: Painel Marketshare - Aprendiz | C541: =IF(B541<>"",VLOOKUP(B541,Projetos!E:F,2,0),"") -> 16 | E541: Painel | F541: Alteração e Ajuste | G541: Paulo Vinicius | H541: 45456 | I541: 0.16666667 | J541: Finalizado
B542: Painel Marketshare - Aprendiz | C542: =IF(B542<>"",VLOOKUP(B542,Projetos!E:F,2,0),"") -> 16 | E542: Reunião | F542: Aprovação com o Diego | G542: Paulo Vinicius | H542: 45456 | I542: 0.013888889 | J542: Finalizado
B543: Implantação Amazon | C543: =IF(B543<>"",VLOOKUP(B543,Projetos!E:F,2,0),"") -> 18 | E543: Tratamento de Dados | F543: Incluindo tabelas de Apoio | G543: Alexandre Borges | H543: 45456 | I543: 0.29166667 | J543: Finalizado
B544: Atualização Painel Mercado | C544: =IF(B544<>"",VLOOKUP(B544,Projetos!E:F,2,0),"") -> 25 | E544: Painel | F544: Ajuste na tabela d 0 E | G544: Bruno Felipe | H544: 45456 | I544: 0.083333333 | J544: Finalizado
B545: Painel Marketshare - Aprendiz | C545: =IF(B545<>"",VLOOKUP(B545,Projetos!E:F,2,0),"") -> 16 | E545: Painel | F545: Alteração e Ajuste | G545: Bruno Felipe | H545: 45456 | I545: 0.20833333 | J545: Finalizado
B546: Painel Marketshare - Aprendiz | C546: =IF(B546<>"",VLOOKUP(B546,Projetos!E:F,2,0),"") -> 16 | E546: Reunião | F546: Aprovação com o Diego | G546: Bruno Felipe | H546: 45456 | I546: 0.013888889 | J546: Finalizado
B547: Projetos e Atividades Internas | C547: =IF(B547<>"",VLOOKUP(B547,Projetos!E:F,2,0),"") -> 30 | E547: Reunião | F547: Reunião para alinhamento | G547: Marcus Vinícius | H547: 45456 | I547: 0.16666667 | J547: Finalizado
B548: Livro IFC | C548: =IF(B548<>"",VLOOKUP(B548,Projetos!E:F,2,0),"") -> 13 | E548: Estruturação do Projeto | F548: Reunião de Alinhamentos e ajustes do projeto IFC | G548: Ely Bastos | H548: 45457 | I548: 0.16666667 | J548: Finalizado
B549: Livro IFC | C549: =IF(B549<>"",VLOOKUP(B549,Projetos!E:F,2,0),"") -> 13 | E549: Relatório | F549: Escrita de textos do livro IFC | G549: Luis Eduardo | H549: 45457 | I549: 0.20833333 | J549: Finalizado
B550: Projeto Agrodefesa | C550: =IF(B550<>"",VLOOKUP(B550,Projetos!E:F,2,0),"") -> 39 | E550: Estruturação do Projeto | F550: Solicitação de Informações para definição da amostra | G550: Ely Bastos | H550: 45457 | I550: 0.083333333 | J550: Finalizado | K550: Envio par análise da Gerência e posterimente envio para o cliente.
B551: Estudos de Concorrentes RPA | C551: =IF(B551<>"",VLOOKUP(B551,Projetos!E:F,2,0),"") -> 15 | E551: Pesquisa | F551: Mapeamento dos concorrentes dos clientes RPA | G551: Paulo Vinicius | H551: 45457 | I551: 0.19097222 | J551: Finalizado
B552: Iniciativas de Mercados - CMs | C552: 27 | E552: Reunião | F552: planejamento de execução de cada um dos CMs | G552: Paulo Vinicius | H552: 45457 | I552: 0.059027778 | J552: Finalizado
B553: Iniciativas de Mercados - CMs | C553: =IF(B553<>"",VLOOKUP(B553,Projetos!E:F,2,0),"") -> 27 | E553: Reunião | F553: planejamento de execução de cada um dos CMs | G553: Bruno Felipe | H553: 45457 | I553: 0.059027778 | J553: Finalizado
B554: Atualização Painel Mercado | C554: =IF(B554<>"",VLOOKUP(B554,Projetos!E:F,2,0),"") -> 25 | E554: Alteração/Ajustes | F554: Ajustes na tabela entregue, vendido e na aba Analytics | G554: Bruno Felipe | H554: 45457 | I554: 0.125 | J554: Finalizado
B555: Implantação Amazon | C555: =IF(B555<>"",VLOOKUP(B555,Projetos!E:F,2,0),"") -> 18 | E555: Tratamento de Dados | F555: Inserindo tabelas de Apoio (Municipio, CNAE, CBO, CID) | G555: Alexandre Borges | H555: 45457 | I555: 0.29166667 | J555: Finalizado
B556: Atualização Painel Saúde | C556: =IF(B556<>"",VLOOKUP(B556,Projetos!E:F,2,0),"") -> 22 | E556: Tratamento de Dados | F556: Estudos da Base com desenvolvimento dos indicadores | G556: Rodolfo Viscal | H556: 45457 | I556: 0.33333333 | J556: Finalizado | K556: Problemas de conflitos com bases não conversando uma com a outra
B557: Projetos e Atividades Internas | C557: =IF(B557<>"",VLOOKUP(B557,Projetos!E:F,2,0),"") -> 30 | E557: Proposta / Contrato | F557: Estruturação da Proposta Unimed Cerrado | G557: Diego Gomes | H557: 45457 | I557: 0.29166667 | J557: Finalizado
B558: Banco de Dados Mineração | C558: =IF(B558<>"",VLOOKUP(B558,Projetos!E:F,2,0),"") -> 24 | E558: Alteração/Ajustes | F558: Alteração nos scripts e novos testes | G558: Marcus Vinícius | H558: 45457 | I558: 0.25 | J558: Finalizado
B559: Atualização Painel Saúde | C559: =IF(B559<>"",VLOOKUP(B559,Projetos!E:F,2,0),"") -> 22 | E559: Tratamento de Dados | F559: Estudos da Base com desenvolvimento dos indicadores | G559: Rodolfo Viscal | H559: 45458 | I559: 0.33333333 | J559: Finalizado
B560: Livro IFC | C560: =IF(B560<>"",VLOOKUP(B560,Projetos!E:F,2,0),"") -> 13 | E560: Relatório | F560: Escrita de textos do livro IFC | G560: Luis Eduardo | H560: 45460 | I560: 0.16666667 | J560: Finalizado
B561: PDE - Serra Verde | C561: =IF(B561<>"",VLOOKUP(B561,Projetos!E:F,2,0),"") -> 3 | E561: Reunião | F561: Reunião sobre manual PDE | G561: Luis Eduardo | H561: 45460 | I561: 0.083333333 | J561: Finalizado
B562: Estudos de Concorrentes RPA | C562: =IF(B562<>"",VLOOKUP(B562,Projetos!E:F,2,0),"") -> 15 | E562: Coleta | F562: Lista de prospecção | G562: Paulo Vinicius | H562: 45460 | I562: 0.25 | J562: Finalizado
B563: Painel de Gestão | C563: =IF(B563<>"",VLOOKUP(B563,Projetos!E:F,2,0),"") -> 23 | E563: Painel | F563: atividades do colaboradores com a base | G563: Rodolfo Viscal | H563: 45460 | I563: 0.33333333 | J563: Finalizado
...

Sheet Projetos
A2: Cod Área | B2: Área Observatório | C2: Área | D2: Líder do Projeto | E2: Nome do Projeto | F2: Cod Projeto | G2: Lista do Projeto | H2: Data Início do Projeto | I2: Data Término do Projeto | J2: Total de Horas | K2: Status | L2: Total do Projeto (R$) | M2: Realizado (R$) | N2: Fonte de Recursos | O2: Classe | P2: Cliente Final
A3: 1 | B3: Observatorio | C3: Inteligência de Dados | D3: Diego Gomes | E3: Atualização de Painel - Educação | F3: 1 | H3: 45402 | I3: 45427 | J3: 108 | K3: Finalizado | L3: 3780 | N3: Institucional | O3: Atualização | P3: OBSERVATORIO
A4: 1 | B4: Observatorio | C4: Inteligência de Dados | D4: Diego Gomes | E4: Perfil dos Municípios | F4: 2 | G4: Perfil_dos_Municípios | H4: 45301 | I4: 45382 | J4: 528 | K4: Em andamento | L4: 18480 | N4: Institucional | O4: Atualização | P4: OBSERVATORIO
A5: 1 | B5: Observatorio | C5: Inteligência Competitiva | D5: Ely Bastos | E5: PDE - Serra Verde | F5: 3 | G5: PDE_Serra_Verde | H5: 45432 | I5: 45443 | J5: 480 | K5: Em andamento | L5: 20000 | N5: Institucional | O5: Pesquisa | P5: IEL - PDF
A6: 1 | B6: Observatorio | C6: Inteligência de Dados | D6: Diego Gomes | E6: Atualização da Base de Dados FIEG | F6: 4 | H6: 45343 | I6: 45348 | J6: 8 | K6: Finalizado | L6: 520 | N6: Institucional | O6: Atualização | P6: FIEG
A7: 1 | B7: Observatorio | C7: Inteligência de Dados | D7: Diego Gomes | E7: Validação Lista de Empresas - DAIA | F7: 5 | H7: 45330 | I7: 45338 | J7: 6 | K7: Finalizado | L7: 390 | N7: Institucional | O7: Banco de Dados | P7: SINDICATOS
A8: 1 | B8: Observatorio | C8: Inteligência de Dados | D8: Diego Gomes | E8: Relatório Rotatividade Farmoquímico | F8: 6 | H8: 45336 | I8: 45338 | J8: 11 | K8: Finalizado | L8: 715 | N8: Institucional | O8: Banco de Dados | P8: SINDICATOS
A9: 1 | B9: Observatorio | C9: Inteligência de Dados | D9: Diego Gomes | E9: Relatório Sindmóveis | F9: 7 | H9: 45331 | I9: 45337 | J9: 5 | K9: Finalizado | L9: 325 | N9: Institucional | O9: Banco de Dados | P9: SINDICATOS
A10: 1 | B10: Observatorio | C10: Inteligência de Dados | D10: Diego Gomes | E10: Lista de Empresas Confecção | F10: 8 | H10: 45340 | I10: 45341 | J10: 5 | K10: Finalizado | L10: 325 | N10: Institucional | O10: Banco de Dados | P10: SINDICATOS
A11: 1 | B11: Observatorio | C11: Inteligência de Dados | D11: Diego Gomes | E11: Apresentação Descarbonização da Mineração | F11: 9 | H11: 45313 | I11: 45345 | J11: 37 | K11: Finalizado | L11: 2405 | N11: Institucional | O11: Banco de Dados | P11: FIEG
A12: 1 | B12: Observatorio | C12: Inteligência Competitiva | D12: Ely Bastos | E12: Relatório de Sustentabilidade - IEL | F12: 10 | H12: 45301 | I12: 45427 | J12: 596 | K12: Finalizado | L12: 32780 | N12: Institucional | O12: Banco de Dados | P12: IEL - MERCADO
A13: 1 | B13: Observatorio | C13: Inteligência de Dados | D13: Diego Gomes | E13: Atualização e Melhoria do IFC | F13: 11 | H13: 45313 | I13: 45387 | J13: 264 | K13: Finalizado | L13: 9240 | N13: Institucional | O13: Banco de Dados | P13: IEL - SUPERINTENDÊNCIA
A14: 1 | B14: Observatorio | C14: Inteligência de Mercado | D14: Bruno Felipe | E14: Estudo de Microregiões - Ceres | F14: 12 | H14: 45369 | I14: 45380 | J14: 129 | K14: Finalizado | L14: 4515 | N14: Institucional | O14: Estudo | P14: IEL - MERCADO
A15: 1 | B15: Observatorio | C15: Inteligência Competitiva | D15: Ely Bastos | E15: Livro IFC | F15: 13 | H15: 45371 | I15: 45402 | J15: 331 | K15: Finalizado | L15: 18205 | N15: Institucional | O15: Estudo | P15: OBSERVATORIO
A16: 1 | B16: Observatorio | C16: Inteligência de Mercado | D16: Bruno Felipe | E16: Marketshare Estágio | F16: 14 | H16: 45377 | I16: 45439 | J16: 80 | K16: Finalizado | L16: 2800 | N16: Institucional | O16: Pesquisa | P16: IEL - MERCADO
A17: 1 | B17: Observatorio | C17: Inteligência de Mercado | D17: Bruno Felipe | E17: Estudos de Concorrentes RPA | F17: 15 | H17: 45390 | I17: 45471 | J17: 149 | K17: Parado | L17: 5215 | N17: Institucional | O17: Pesquisa | P17: IEL - MERCADO
... A19: 1 | B19: Observatorio | C19: Inteligência de Mercado | D19: Bruno Felipe | E19: Painel Marketshare - Estágio | F19: 17 | H19: 45377 | I19: 45439 | J19: 90 | K19: Finalizado | L19: 700 | N19: Institucional | O19: Atualização | P19: OBSERVATORIO
A20: 1 | B20: Observatorio | C20: Inteligência de Dados | D20: Alexandre Borges | E20: Implantação Amazon | F20: 18 | G20: Implantação_Amazon | H20: 45383 | I20: 45534 | J20: 300 | K20: Em andamento | L20: 18000 | N20: Institucional | O20: Atualização | P20: OBSERVATORIO
A21: 1 | B21: Observatorio | C21: Inteligência de Dados | D21: Alexandre Borges | E21: MTE - CAGED | F21: 19 | G21: MTE_CAGED | H21: 45292 | I21: 45657 | J21: 90 | K21: Em andamento | L21: 5850 | N21: Institucional | O21: Banco de Dados | P21: OBSERVATORIO
A22: 1 | B22: Observatorio | C22: Inteligência de Dados | D22: Alexandre Borges | E22: MTE - RAIS | F22: 20 | H22: 45292 | I22: 45657 | J22: 45 | K22: Em andamento | L22: 2475 | N22: Institucional | O22: Banco de Dados | P22: OBSERVATORIO
A23: 1 | B23: Observatorio | C23: Inteligência de Dados | D23: Marcus Vinícius | E23: Panorama Econômico | F23: 21 | G23: Panorama_Econômico | H23: 45292 | I23: 45657 | J23: 264 | K23: Em andamento | L23: 14520 | N23: Institucional | O23: Banco de Dados | P23: OBSERVATORIO
A24: 1 | B24: Observatorio | C24: Inteligência de Dados | D24: Rodolfo Viscal | E24: Atualização Painel Saúde | F24: 22 | H24: 45413 | I24: 45504 | J24: 700 | K24: Finalizado | L24: 31500 | N24: Institucional | O24: Atualização | P24: OBSERVATORIO
A25: 1 | B25: Observatorio | C25: Gestão | D25: Rodolfo Viscal | E25: Painel de Gestão | F25: 23 | G25: Painel_de_Gestão | H25: 45446 | I25: 45504 | J25: 250 | K25: Em andamento | L25: 12500 | N25: Institucional | O25: Painel | P25: OBSERVATORIO
A26: 1 | B26: Observatorio | C26: Inteligência de Dados | D26: Marcus Vinícius | E26: Banco de Dados Mineração | F26: 24 | G26: Banco_de_Dados_Mineração | H26: 45453 | I26: 45504 | J26: 106 | K26: Em andamento | L26: 5830 | N26: Institucional | O26: Banco de Dados | P26: OBSERVATORIO
A27: 1 | B27: Observatorio | C27: Inteligência de Mercado | D27: Bruno Felipe | E27: Atualização Painel Mercado | F27: 25 | G27: Atualização_Painel_Mercado | H27: 45446 | I27: 45657 | J27: 118 | K27: Em andamento | L27: 5310 | N27: Institucional | O27: Painel | P27: IEL - MERCADO
A28: 1 | B28: Observatorio | C28: Inteligência Competitiva | D28: Ely Bastos | E28: Diagnóstico dos Produtores da Agrodefesa | F28: 26 | H28: 45456 | I28: 45657 | J28: 100 | K28: Parado | L28: 5500 | N28: Mercado | O28: Estudo | P28: MERCADO
A29: 1 | B29: Observatorio | C29: Inteligência de Mercado | D29: Bruno Felipe | E29: Iniciativas de Mercados - CMs | F29: 27 | G29: Iniciativas_de_Mercados_CMs | H29: 45453 | I29: 45657 | J29: 120 | K29: Em andamento | L29: 5400 | N29: Institucional | O29: Estudo | P29: IEL - MERCADO
A30: 1 | B30: Observatorio | C30: Inteligência de Mercado | D30: Bruno Felipe | E30: Painel de Clientes | F30: 28 | H30: 45413 | I30: 45504 | J30: 80 | K30: Finalizado | L30: 2800 | N30: Institucional | O30: Painel | P30: IEL - MERCADO
A31: 1 | B31: Observatorio | C31: Inteligência de Mercado | D31: Bruno Felipe | E31: Newsletter PIM-PF | F31: 29 | H31: 45413 | I31: 45657 | J31: 60 | K31: Finalizado | L31: 2100 | N31: Institucional | O31: Estudo | P31: OBSERVATORIO
A32: 1 | B32: Observatorio | C32: Inteligência de Dados | D32: Diego Gomes | E32: Projetos e Atividades Internas | F32: 30 | G32: Projetos_e_Atividades_Internas | H32: 45292 | I32: 45657 | J32: 300 | K32: Em andamento | L32: 16500 | N32: Institucional | O32: Estudo | P32: OBSERVATORIO
A33: 1 | B33: Observatorio | C33: Gestão | D33: Diego Gomes | E33: Observatório Nacional | F33: 31 | G33: Observatório_Nacional | H33: 45444 | I33: 45657 | J33: 300 | K33: Em andamento | L33: 16500 | N33: Institucional | O33: Planejamento | P33: OBSERVATORIO
A34: 1 | B34: Observatorio | C34: Inteligência de Dados | D34: Diego Gomes | E34: Treinamentos e Capacitações | F34: 32 | G34: Treinamentos_e_Capacitações | H34: 45444 | I34: 45657 | J34: 400 | K34: Em andamento | L34: 26000 | N34: Institucional | O34: Planejamento | P34: OBSERVATORIO
A35: 1 | B35: Observatorio | C35: Inteligência de Mercado | D35: Bruno Felipe | E35: Painel Institucional - Superintendência | F35: 33 | G35: Painel_Institucional_Superintendência | H35: 45444 | I35: 45657 | J35: 300 | K35: Em andamento | L35: 16500 | N35: Institucional | O35: Planejamento | P35: IEL - SUPERINTENDÊNCIA
A36: 1 | B36: Observatorio | C36: Inteligência de Mercado | D36: Bruno Felipe | E36: Pré-projeto Monitora Linkedin | F36: 34 | H36: 45468 | I36: 45469 | J36: 28 | K36: Finalizado | L36: 980 | N36: Institucional | O36: Painel | P36: IEL - MERCADO
A37: 1 | B37: Observatorio | C37: Inteligência de Mercado | D37: Bruno Felipe | E37: Painel Utilidades - Mercado | F37: 35 | G37: Painel_Utilidades_Mercado | H37: 45444 | I37: 45657 | J37: 300 | K37: Em andamento | L37: 16500 | N37: Institucional | O37: Painel | P37: IEL - MERCADO
A38: 1 | B38: Observatorio | C38: Gestão | D38: Isadora Pereira | E38: Gestão do Conhecimento | F38: 36 | G38: Gestão_do_Conhecimento | H38: 45352 | I38: 45657 | J38: 80 | K38: Em andamento | L38: 2000 | N38: Institucional | O38: Planejamento | P38: OBSERVATORIO
A39: 1 | B39: Observatorio | C39: Gestão | D39: Isadora Pereira | E39: Gestão de Portfólio | F39: 37 | G39: Gestão_de_Portfólio | H39: 45292 | I39: 45657 | J39: 80 | K39: Em andamento | L39: 2001 | N39: Institucional | O39: Planejamento | P39: OBSERVATORIO
A40: 1 | B40: Observatorio | C40: Inteligência de Dados | D40: Paulo Vinicius | E40: Relatório Município de Nova Roma | F40: 38 | H40: 45471 | I40: 45474 | J40: 7 | K40: Finalizado | L40: 245 | N40: Institucional | O40: Banco de Dados | P40: SESI
A41: 1 | B41: Observatorio | C41: Inteligência Competitiva | D41: Ely Bastos | E41: Projeto Agrodefesa | F41: 39 | G41: Projeto_Agrodefesa | H41: 45444 | I41: 45657 | J41: 600 | K41: Em andamento | L41: 105033.5 | N41: Mercado | O41: Pesquisa | P41: MERCADO
A42: 1 | B42: Observatorio | C42: Inteligência de Mercado | D42: Paulo Vinicius | E42: Painel Aprendizagem - SENAI | F42: 40 | G42: Painel_Aprendizagem_SENAI | H42: 45474 | I42: 45657 | J42: 100 | K42: Em andamento | L42: 3500 | N42: Institucional | O42: Painel | P42: IEL - MERCADO
...

Sheet Tabela Hora x Custo Colaborador
B2: COD | C2: Modelo de Contrato | D2: Colaboradores | E2: Função | F2: Carga horário diária | G2: Carga horário Mensal | H2: Valor Hora (R$)
B3: 1 | C3: CLT | D3: Sandra Marcia | E3: Gerente | F3: 8 | G3: 160 | H3: 150
B4: 2 | C4: CLT | D4: Diego Gomes | E4: Cientista de Dados | F4: 8 | G4: 160 | H4: 65
B5: 3 | C5: CLT | D5: Alexandre Borges | E5: Engenheiro de Dados | F5: 8 | G5: 160 | H5: 55
B6: 4 | C6: Prestador | D6: Rodolfo Viscal | E6: Analista de BI | F6: 8 | G6: 160 | H6: 35
B7: 5 | C7: Prestador | D7: Marcus Vinícius | E7: Estagiário de T.I | F7: 8 | G7: 160 | H7: 35
B8: 6 | C8: CLT | D8: Fernanda Heleno | E8: Analista de Pesquisa | F8: 8 | G8: 160 | H8: 45
B9: 7 | C9: CLT | D9: Ely Bastos | E9: Analista de Relatório | F9: 8 | G9: 160 | H9: 55
B10: 8 | C10: Estagiário | D10: Luis Eduardo | E10: Estagiário de Economia | F10: 6 | G10: 120 | H10: 15
B11: 9 | C11: Estagiário | D11: Nicoly Pacheco | E11: Estagiária de Economia | F11: 6 | G11: 120 | H11: 15
B12: 10 | C12: CLT | D12: Bruno Felipe | E12: Assistente de Dados | F12: 8 | G12: 160 | H12: 25
B13: 11 | C13: Estagiário | D13: Paulo Vinicius | E13: Estagiário de Economia | F13: 6 | G13: 120 | H13: 15
B14: 12 | C14: CLT | D14: Isadora Pereira | E14: Assistente de Projetos | F14: 8 | G14: 160 | H14: 25
... B16: 14 | C16: Estagiário | D16: Antônio Guido | E16: Estagiária de Economia | F16: 6 | G16: 120 | H16: 15

Sheet Classe do Projeto
B2: Classe
B3: Painel
B4: Estudo
B5: Pesquisa
B6: Banco de Dados
B7: Correção
B8: Atualização
B9: Planejamento

Sheet Cliente Final
B2: Cliente Final
B3: FIEG
B4: IEL - PDF
B5: IEL - MERCADO
B6: IEL - APRENDIZ
B7: SINDICATOS
B8: MERCADO
B9: OBSERVATORIO
B10: IEL - SUPERINTENDÊNCIA
B11: SENAI
B12: SESI

Sheet Fontes de Recursos
B2: Fonte do Recurso
B3: Institucional
B4: Mercado

Sheet Status do Projeto
B2: Status
B3: Não Iniciado
B4: Em andamento
B5: Parado
B6: Finalizado

Sheet Áreas da Demanda
B2: Área
B3: Inteligência de Dados
B4: Inteligência Competitiva
B5: Inteligência de Mercado
B6: Gestão

Sheet Etapas Macro
A1: Etapas Macro
A2: Alteração/Ajustes
A3: Estruturação do Projeto
A4: Extração de Dados
A5: Identificação de Indicadores
A6: Painel
A7: Planejamento do Projeto
A8: Relatório
A9: Reunião
A10: Tratamento de Dados
A11: Validação
A12: Coleta
... A21: Monitoramento

Sheet Planilha1
A1: 1 | B1: 2 | C1: 3 | D1: 4 | E1: 5 | F1: 6 | G1: 7 | H1: 8 | I1: 9 | J1: 10 | K1: 11 | L1: 12 | M1: 13 | N1: 14 | O1: 15 | P1: 16 | Q1: 17 | R1: 18 | S1: 19 | T1: 20 | U1: 21 | V1: 22 | W1: O23 | X1: 24 | Y1: 25 | Z1: 26 | AA1: 27 | AB1: 28 | AC1: 29 | AD1: 30 | AE1: 31 | AF1: 32 | AG1: 33 | AH1: 34 | AI1: 35 | AJ1: 36 | AK1: 37 | AL1: 38 | AM1: 39 | AN1: 40 | AO1: 41 | AP1: 42 | AQ1: 43 | AR1: 44 | AS1: 45 | AT1: 46 | AU1: 47 | AV1: 48
A2: Planejamento do Projeto | B2: Planejamento do Projeto | C2: Coleta | D2: Reunião | E2: Reunião | F2: Reunião | G2: Reunião | H2: Reunião | I2: Reunião | J2: Reunião | K2: Reunião | L2: Reunião | M2: Reunião | N2: Reunião | O2: Reunião | P2: Reunião | Q2: Reunião | R2: Estruturação do Projeto | S2: Atualização | T2: Atualização | U2: Atualização | V2: Estruturação do Projeto | W2: Reunião | X2: Reunião | Y2: Reunião | AA2: Planejamento do Projeto | AB2: Planejamento do Projeto | AC2: Planejamento do Projeto | AD2: Reunião | AE2: Reunião | AF2: Capacitação | AG2: Alteração/Ajustes | AH2: Estruturação do Projeto | AJ2: Planejamento do Projeto | AK2: Planejamento do Projeto | AL2: Tratamento de Dados | AM2: Reunião
A3: Extração de Dados | B3: Estruturação do Projeto | C3: Tabulação | D3: Extração de Dados | E3: Extração de Dados | F3: Extração de Dados | G3: Extração de Dados | H3: Extração de Dados | I3: Estruturação do Projeto | J3: Extração de Dados | K3: Estruturação do Projeto | L3: Planejamento do Projeto | M3: Relatório | N3: Estruturação do Projeto | O3: Estruturação do Projeto | P3: Estruturação do Projeto | Q3: Estruturação do Projeto | R3: Alteração/Ajustes | S3: Extração de Dados | T3: Extração de Dados | U3: Extração de Dados | V3: Identificação de Indicadores | W3: Estruturação do Projeto | X3: Extração de Dados | Y3: Alteração/Ajustes | AA3: Identificação de Indicadores | AB3: Identificação de Indicadores | AC3: Identificação de Indicadores | AD3: Estruturação do Projeto | AE3: Relatório | AG3: Atualização | AH3: Relatório | AJ3: Diagnóstico | AK3: Diagnóstico | AL3: Relatório | AM3: Planejamento do Projeto
A4: Tratamento de Dados | B4: Extração de Dados | C4: Relatório | D4: Tratamento de Dados | E4: Tratamento de Dados | F4: Tratamento de Dados | G4: Tratamento de Dados | H4: Tratamento de Dados | I4: Relatório | J4: Tratamento de Dados | K4: Identificação de Indicadores | L4: Identificação de Indicadores | M4: Tratamento de Dados | N4: Identificação de Indicadores | O4: Extração de Dados | P4: Extração de Dados | Q4: Extração de Dados | R4: Extração de Dados | S4: Tratamento de Dados | T4: Tratamento de Dados | U4: Tratamento de Dados | V4: Extração de Dados | W4: Tratamento de Dados | X4: Tratamento de Dados | Y4: Extração de Dados | AA4: Tratamento de Dados | AB4: Tratamento de Dados | AC4: Tratamento de Dados | AD4: Proposta / Contrato | AE4: Atualização | AJ4: Reunião | AK4: Reunião | AL4: Validação | AM4: Proposta / Contrato
A5: Painel | B5: Tratamento de Dados | C5: Alteração/Ajustes | D5: Validação | E5: Validação | F5: Alteração/Ajustes | G5: Validação | H5: Validação | I5: Validação | J5: Relatório | K5: Validação | L5: Extração de Dados | M5: Validação | N5: Extração de Dados | O5: Tratamento de Dados | P5: Tratamento de Dados | Q5: Tratamento de Dados | R5: Tratamento de Dados | S5: Painel | T5: Painel | V5: Tratamento de Dados | W5: Painel | X5: Validação | Y5: Tratamento de Dados | AA5: Relatório | AB5: Relatório | AC5: Relatório | AD5: Extração de Dados | AJ5: Implementação | AK5: Implementação | AM5: Diagnóstico
A6: Alteração/Ajustes | B6: Painel | I6: Alteração/Ajustes | J6: Validação | K6: Extração de Dados | L6: Tratamento de Dados | M6: Alteração/Ajustes | N6: Tratamento de Dados | O6: Relatório | P6: Painel | Q6: Painel | S6: Alteração/Ajustes | T6: Alteração/Ajustes | V6: Painel | W6: Alteração/Ajustes | AA6: Alteração/Ajustes | AB6: Alteração/Ajustes | AC6: Alteração/Ajustes | AJ6: Diagnóstico | AK6: Diagnóstico | AM6: Coleta
B7: Validação | J7: Alteração/Ajustes | K7: Tratamento de Dados | L7: Relatório | N7: Relatório | O7: Validação | P7: Relatório | Q7: Relatório | V7: Validação | AM7: Tabulação
B8: Reunião | K8: Painel | L8: Validação | N8: Painel | O8: Pesquisa | P8: Alteração/Ajustes | Q8: Alteração/Ajustes | V8: Alteração/Ajustes | AM8: Tratamento de Dados
K9: Relatório | N9: Validação | O9: Apresentação/Entrega | AM9: Painel
K10: Alteração/Ajustes | AM10: Relatório
AM11: Validação

Sheet Subetapas do projeto
B2: Nome do Projeto | C2: Cod Projeto | D2: Atividades Macro | E2: Horas Estimadas | F2: Status | I2: Nome do Projeto | J2: Cod Projeto | K2: Atividades | M2: Nome do Projeto | N2: Cod Projeto | O2: Atividades | Q2: Nome do Projeto | R2: Cod Projeto | S2: Atividades | U2: Nome do Projeto | V2: Cod Projeto | W2: Atividades
B3: Atualização de Painel - Educação | C3: =IF(B3<>"",VLOOKUP(B3,Projetos!E:F,2,0),"") -> 1 | D3: Planejamento do Projeto | E3: 6 | F3: Finalizado | I3: Projeto Agrodefesa | J3: 39 | K3: Reunião | M3: Implantação Amazon | N3: 18 | O3: Estruturação do Projeto | Q3: Banco de Dados Mineração | R3: 24 | S3: Reunião | U3: Observatório Nacional | V3: 31 | W3: Reunião
B4: Atualização de Painel - Educação | C4: =IF(B4<>"",VLOOKUP(B4,Projetos!E:F,2,0),"") -> 1 | D4: Extração de Dados | E4: 16 | F4: Finalizado | I4: Projeto Agrodefesa | J4: 39 | K4: Planejamento do Projeto | M4: Implantação Amazon | N4: 18 | O4: Alteração/Ajustes | Q4: Banco de Dados Mineração | R4: 24 | S4: Extração de Dados | U4: Observatório Nacional | V4: 31 | W4: Relatório
B5: Atualização de Painel - Educação | C5: =IF(B5<>"",VLOOKUP(B5,Projetos!E:F,2,0),"") -> 1 | D5: Tratamento de Dados | E5: 16 | F5: Finalizado | I5: Projeto Agrodefesa | J5: 39 | K5: Proposta / Contrato | M5: Implantação Amazon | N5: 18 | O5: Extração de Dados | Q5: Banco de Dados Mineração | R5: 24 | S5: Tratamento de Dados | U5: Observatório Nacional | V5: 31 | W5: Atualização
B6: Atualização de Painel - Educação | C6: =IF(B6<>"",VLOOKUP(B6,Projetos!E:F,2,0),"") -> 1 | D6: Painel | E6: 60 | F6: Finalizado | I6: Projeto Agrodefesa | J6: 39 | K6: Diagnóstico | M6: Implantação Amazon | N6: 18 | O6: Tratamento de Dados | Q6: Banco de Dados Mineração | R6: 24 | S6: Validação
B7: Atualização de Painel - Educação | C7: =IF(B7<>"",VLOOKUP(B7,Projetos!E:F,2,0),"") -> 1 | D7: Alteração/Ajustes | E7: 10 | F7: Finalizado | I7: Projeto Agrodefesa | J7: 39 | K7: Coleta | U7: Nome do Projeto | V7: Cod Projeto | W7: Atividades
B8: Perfil dos Municípios | C8: =IF(B8<>"",VLOOKUP(B8,Projetos!E:F,2,0),"") -> 2 | D8: Planejamento do Projeto | E8: 10 | F8: Finalizado | I8: Projeto Agrodefesa | J8: 39 | K8: Tabulação | M8: Nome do Projeto | N8: Cod Projeto | O8: Atividades | Q8: Nome do Projeto | R8: Cod Projeto | S8: Atividades | U8: Treinamentos e Capacitações | V8: 32 | W8: Capacitação
B9: Perfil dos Municípios | C9: =IF(B9<>"",VLOOKUP(B9,Projetos!E:F,2,0),"") -> 2 | D9: Estruturação do Projeto | E9: 6 | F9: Finalizado | I9: Projeto Agrodefesa | J9: 39 | K9: Tratamento de Dados | M9: MTE - CAGED | N9: 19 | O9: Atualização | Q9: Atualização Painel Mercado | R9: 25 | S9: Reunião
B10: Perfil dos Municípios | C10: =IF(B10<>"",VLOOKUP(B10,Projetos!E:F,2,0),"") -> 2 | D10: Extração de Dados | E10: 170 | F10: Finalizado | I10: Projeto Agrodefesa | J10: 39 | K10: Painel | M10: MTE - CAGED | N10: 19 | O10: Extração de Dados | Q10: Atualização Painel Mercado | R10: 25 | S10: Alteração/Ajustes | U10: Nome do Projeto | V10: Cod Projeto | W10: Atividades
B11: Perfil dos Municípios | C11: =IF(B11<>"",VLOOKUP(B11,Projetos!E:F,2,0),"") -> 2 | D11: Tratamento de Dados | E11: 104 | F11: Finalizado | I11: Projeto Agrodefesa | J11: 39 | K11: Relatório | M11: MTE - CAGED | N11: 19 | O11: Tratamento de Dados | Q11: Atualização Painel Mercado | R11: 25 | S11: Extração de Dados | U11: Painel Institucional - Superintendência | V11: 33 | W11: Alteração/Ajustes
B12: Perfil dos Municípios | C12: =IF(B12<>"",VLOOKUP(B12,Projetos!E:F,2,0),"") -> 2 | D12: Painel | E12: 232 | F12: Finalizado | I12: Projeto Agrodefesa | J12: 39 | K12: Validação | M12: MTE - CAGED | N12: 19 | O12: Painel | Q12: Atualização Painel Mercado | R12: 25 | S12: Tratamento de Dados | U12: Painel Institucional - Superintendência | V12: 33 | W12: Atualização
B13: Perfil dos Municípios | C13: =IF(B13<>"",VLOOKUP(B13,Projetos!E:F,2,0),"") -> 2 | D13: Validação | E13: 6 | F13: Finalizado | M13: MTE - CAGED | N13: 19 | O13: Alteração/Ajustes
B14: PDE - Serra Verde | C14: =IF(B14<>"",VLOOKUP(B14,Projetos!E:F,2,0),"") -> 3 | D14: Reunião | E14: 96 | F14: Em andamento | Q14: Nome do Projeto | R14: Cod Projeto | S14: Atividades | U14: Nome do Projeto | V14: Cod Projeto | W14: Atividades
B15: PDE - Serra Verde | C15: =IF(B15<>"",VLOOKUP(B15,Projetos!E:F,2,0),"") -> 3 | D15: Coleta | E15: 96 | F15: Em andamento | I15: Nome do Projeto | J15: Cod Projeto | K15: Atividades | M15: Nome do Projeto | N15: Cod Projeto | O15: Atividades | Q15: Iniciativas de Mercados - CMs | R15: 27 | S15: Planejamento do Projeto | U15: Gestão do Conhecimento | V15: 36 | W15: Planejamento do Projeto
B16: PDE - Serra Verde | C16: =IF(B16<>"",VLOOKUP(B16,Projetos!E:F,2,0),"") -> 3 | D16: Tabulação | E16: 96 | F16: Em andamento | I16: PDE - Serra Verde | J16: 3 | K16: Reunião | M16: Panorama Econômico | N16: 21 | O16: Atualização | Q16: Iniciativas de Mercados - CMs | R16: 27 | S16: Identificação de Indicadores | U16: Gestão do Conhecimento | V16: 36 | W16: Diagnóstico
B17: PDE - Serra Verde | C17: =IF(B17<>"",VLOOKUP(B17,Projetos!E:F,2,0),"") -> 3 | D17: Relatório | E17: 96 | F17: Em andamento | I17: PDE - Serra Verde | J17: 3 | K17: Coleta | M17: Panorama Econômico | N17: 21 | O17: Extração de Dados | Q17: Iniciativas de Mercados - CMs | R17: 27 | S17: Tratamento de Dados | U17: Gestão do Conhecimento | V17: 36 | W17: Reunião
B18: PDE - Serra Verde | C18: =IF(B18<>"",VLOOKUP(B18,Projetos!E:F,2,0),"") -> 3 | D18: Alteração/Ajustes | E18: 96 | F18: Em andamento | I18: PDE - Serra Verde | J18: 3 | K18: Tabulação | Q18: Iniciativas de Mercados - CMs | R18: 27 | S18: Relatório | U18: Gestão do Conhecimento | V18: 36 | W18: Implementação
B19: Atualização da Base de Dados FIEG | C19: =IF(B19<>"",VLOOKUP(B19,Projetos!E:F,2,0),"") -> 4 | D19: Reunião | E19: 1 | F19: Finalizado | I19: PDE - Serra Verde | J19: 3 | K19: Relatório | M19: Nome do Projeto | N19: Cod Projeto | O19: Atividades | Q19: Iniciativas de Mercados - CMs | R19: 27 | S19: Alteração/Ajustes | U19: Gestão do Conhecimento | V19: 36 | W19: Diagnóstico
B20: Atualização da Base de Dados FIEG | C20: =IF(B20<>"",VLOOKUP(B20,Projetos!E:F,2,0),"") -> 4 | D20: Extração de Dados | E20: 2 | F20: Finalizado | I20: PDE - Serra Verde | J20: 3 | K20: Alteração/Ajustes | M20: Painel de Gestão | N20: 23 | O20: Reunião
B21: Atualização da Base de Dados FIEG | C21: =IF(B21<>"",VLOOKUP(B21,Projetos!E:F,2,0),"") -> 4 | D21: Tratamento de Dados | E21: 3 | F21: Finalizado | M21: Painel de Gestão | N21: 23 | O21: Estruturação do Projeto | U21: Nome do Projeto | V21: Cod Projeto | W21: Atividades
B22: Atualização da Base de Dados FIEG | C22: =IF(B22<>"",VLOOKUP(B22,Projetos!E:F,2,0),"") -> 4 | D22: Validação | E22: 2 | F22: Finalizado | M22: Painel de Gestão | N22: 23 | O22: Tratamento de Dados | Q22: Nome do Projeto | R22: Cod Projeto | S22: Atividades | U22: Gestão de Portfólio | V22: 37 | W22: Planejamento do Projeto
B23: Validação Lista de Empresas - DAIA | C23: =IF(B23<>"",VLOOKUP(B23,Projetos!E:F,2,0),"") -> 5 | D23: Reunião | E23: 1 | F23: Finalizado | I23: Nome do Projeto | J23: Cod Projeto | K23: Atividades | M23: Painel de Gestão | N23: 23 | O23: Painel | Q23: Projetos e Atividades Internas | R23: 30 | S23: Reunião | U23: Gestão de Portfólio | V23: 37 | W23: Diagnóstico
B24: Validação Lista de Empresas - DAIA | C24: =IF(B24<>"",VLOOKUP(B24,Projetos!E:F,2,0),"") -> 5 | D24: Extração de Dados | E24: 1 | F24: Finalizado | I24: Demandas Federação (FIEG, SESI e SENAI) | J24: 50 | K24: Reunião | M24: Painel de Gestão | N24: 23 | O24: Alteração/Ajustes | Q24: Projetos e Atividades Internas | R24: 30 | S24: Estruturação do Projeto | U24: Gestão de Portfólio | V24: 37 | W24: Reunião
B25: Validação Lista de Empresas - DAIA | C25: =IF(B25<>"",VLOOKUP(B25,Projetos!E:F,2,0),"") -> 5 | D25: Tratamento de Dados | E25: 3 | F25: Finalizado | I25: Demandas Federação (FIEG, SESI e SENAI) | J25: 50 | K25: Identificação de Indicadores | Q25: Projetos e Atividades Internas | R25: 30 | S25: Proposta / Contrato | U25: Gestão de Portfólio | V25: 37 | W25: Implementação
B26: Validação Lista de Empresas - DAIA | C26: =IF(B26<>"",VLOOKUP(B26,Projetos!E:F,2,0),"") -> 5 | D26: Validação | E26: 1 | F26: Finalizado | I26: Demandas Federação (FIEG, SESI e SENAI) | J26: 50 | K26: Extração de Dados | Q26: Projetos e Atividades Internas | R26: 30 | S26: Extração de Dados | U26: Gestão de Portfólio | V26: 37 | W26: Alteração/Ajustes
B27: Relatório Rotatividade Farmoquímico | C27: =IF(B27<>"",VLOOKUP(B27,Projetos!E:F,2,0),"") -> 6 | D27: Reunião | E27: 1 | F27: Finalizado | I27: Demandas Federação (FIEG, SESI e SENAI) | J27: 50 | K27: Tratamento de Dados
B28: Relatório Rotatividade Farmoquímico | C28: =IF(B28<>"",VLOOKUP(B28,Projetos!E:F,2,0),"") -> 6 | D28: Extração de Dados | E28: 3 | F28: Finalizado | I28: Demandas Federação (FIEG, SESI e SENAI) | J28: 50 | K28: Painel
B29: Relatório Rotatividade Farmoquímico | C29: =IF(B29<>"",VLOOKUP(B29,Projetos!E:F,2,0),"") -> 6 | D29: Tratamento de Dados | E29: 5 | F29: Finalizado | I29: Demandas Federação (FIEG, SESI e SENAI) | J29: 50 | K29: Proposta / Contrato
B30: Relatório Rotatividade Farmoquímico | C30: =IF(B30<>"",VLOOKUP(B30,Projetos!E:F,2,0),"") -> 6 | D30: Alteração/Ajustes | E30: 2 | F30: Finalizado | I30: Demandas Federação (FIEG, SESI e SENAI) | J30: 50 | K30: Alteração/Ajustes
B31: Relatório Sindmóveis | C31: =IF(B31<>"",VLOOKUP(B31,Projetos!E:F,2,0),"") -> 7 | D31: Reunião | E31: 1 | F31: Finalizado | I31: Demandas Federação (FIEG, SESI e SENAI) | J31: 50 | K31: Apresentação/Entrega
B32: Relatório Sindmóveis | C32: =IF(B32<>"",VLOOKUP(B32,Projetos!E:F,2,0),"") -> 7 | D32: Extração de Dados | E32: 2 | F32: Finalizado
B33: Relatório Sindmóveis | C33: =IF(B33<>"",VLOOKUP(B33,Projetos!E:F,2,0),"") -> 7 | D33: Tratamento de Dados | E33: 1 | F33: Finalizado
B34: Relatório Sindmóveis | C34: =IF(B34<>"",VLOOKUP(B34,Projetos!E:F,2,0),"") -> 7 | D34: Validação | E34: 1 | F34: Finalizado
B35: Lista de Empresas Confecção | C35: =IF(B35<>"",VLOOKUP(B35,Projetos!E:F,2,0),"") -> 8 | D35: Reunião | E35: 1 | F35: Finalizado
B36: Lista de Empresas Confecção | C36: =IF(B36<>"",VLOOKUP(B36,Projetos!E:F,2,0),"") -> 8 | D36: Extração de Dados | E36: 2 | F36: Finalizado
B37: Lista de Empresas Confecção | C37: =IF(B37<>"",VLOOKUP(B37,Projetos!E:F,2,0),"") -> 8 | D37: Tratamento de Dados | E37: 1 | F37: Finalizado
B38: Lista de Empresas Confecção | C38: =IF(B38<>"",VLOOKUP(B38,Projetos!E:F,2,0),"") -> 8 | D38: Validação | E38: 1 | F38: Finalizado
B39: Apresentação Descarbonização da Mineração | C39: =IF(B39<>"",VLOOKUP(B39,Projetos!E:F,2,0),"") -> 9 | D39: Reunião | E39: 2 | F39: Finalizado
B40: Apresentação Descarbonização da Mineração | C40: =IF(B40<>"",VLOOKUP(B40,Projetos!E:F,2,0),"") -> 9 | D40: Estruturação do Projeto | E40: 5 | F40: Finalizado
B41: Apresentação Descarbonização da Mineração | C41: =IF(B41<>"",VLOOKUP(B41,Projetos!E:F,2,0),"") -> 9 | D41: Relatório | E41: 24 | F41: Finalizado
...
